

C:\Users\OK\source\repos\Repository4_python\django_test\login_sys_a>
C:\Users\OK\source\repos\Repository4_python\django_test\login_sys_a>python manage.py runserver
Watching for file changes with StatReloader
Performing system checks...

Exception in thread django-main-thread:
Traceback (most recent call last):
  File "C:\Program Files\Python\Python310\lib\threading.py", line 1009, in _bootstrap_inner
    self.run()
  File "C:\Program Files\Python\Python310\lib\threading.py", line 946, in run
    self._target(*self._args, **self._kwargs)
  File "C:\Program Files\Python\Python310\lib\site-packages\django\utils\autoreload.py", line 64, in wrapper
    fn(*args, **kwargs)
  File "C:\Program Files\Python\Python310\lib\site-packages\django\core\management\commands\runserver.py", line 133, in inner_run
    self.check(display_num_errors=True)
  File "C:\Program Files\Python\Python310\lib\site-packages\django\core\management\base.py", line 486, in check
    all_issues = checks.run_checks(
  File "C:\Program Files\Python\Python310\lib\site-packages\django\core\checks\registry.py", line 88, in run_checks
    new_errors = check(app_configs=app_configs, databases=databases)
  File "C:\Program Files\Python\Python310\lib\site-packages\django\core\checks\urls.py", line 14, in check_url_config
    return check_resolver(resolver)
  File "C:\Program Files\Python\Python310\lib\site-packages\django\core\checks\urls.py", line 24, in check_resolver
    return check_method()
  File "C:\Program Files\Python\Python310\lib\site-packages\django\urls\resolvers.py", line 519, in check
    for pattern in self.url_patterns:
  File "C:\Program Files\Python\Python310\lib\site-packages\django\utils\functional.py", line 47, in __get__
    res = instance.__dict__[self.name] = self.func(instance)
  File "C:\Program Files\Python\Python310\lib\site-packages\django\urls\resolvers.py", line 738, in url_patterns
    patterns = getattr(self.urlconf_module, "urlpatterns", self.urlconf_module)
  File "C:\Program Files\Python\Python310\lib\site-packages\django\utils\functional.py", line 47, in __get__
    res = instance.__dict__[self.name] = self.func(instance)
  File "C:\Program Files\Python\Python310\lib\site-packages\django\urls\resolvers.py", line 731, in urlconf_module
    return import_module(self.urlconf_name)
  File "C:\Program Files\Python\Python310\lib\importlib\__init__.py", line 126, in import_module
    return _bootstrap._gcd_import(name[level:], package, level)
  File "<frozen importlib._bootstrap>", line 1050, in _gcd_import
  File "<frozen importlib._bootstrap>", line 1027, in _find_and_load
  File "<frozen importlib._bootstrap>", line 1006, in _find_and_load_unlocked
  File "<frozen importlib._bootstrap>", line 688, in _load_unlocked
  File "<frozen importlib._bootstrap_external>", line 883, in exec_module
  File "<frozen importlib._bootstrap>", line 241, in _call_with_frames_removed
  File "C:\Users\OK\source\repos\Repository4_python\django_test\login_sys_a\project\urls.py", line 23, in <module>
    path('', include("accounts.urls")) # accounts.urls.pyを読み込むための設定を追加
  File "C:\Program Files\Python\Python310\lib\site-packages\django\urls\conf.py", line 39, in include
    urlconf_module = import_module(urlconf_module)
  File "C:\Program Files\Python\Python310\lib\importlib\__init__.py", line 126, in import_module
    return _bootstrap._gcd_import(name[level:], package, level)
  File "<frozen importlib._bootstrap>", line 1050, in _gcd_import
  File "<frozen importlib._bootstrap>", line 1027, in _find_and_load
  File "<frozen importlib._bootstrap>", line 1006, in _find_and_load_unlocked
  File "<frozen importlib._bootstrap>", line 688, in _load_unlocked
  File "<frozen importlib._bootstrap_external>", line 883, in exec_module
  File "<frozen importlib._bootstrap>", line 241, in _call_with_frames_removed
  File "C:\Users\OK\source\repos\Repository4_python\django_test\login_sys_a\accounts\urls.py", line 8, in <module>
    path("", views.IndexView.as_view(), name="index"),
AttributeError: module 'accounts.views' has no attribute 'IndexView'
C:\Users\OK\source\repos\Repository4_python\django_test\login_sys_a\accounts\urls.py changed, reloading.
Watching for file changes with StatReloader
Performing system checks...

System check identified no issues (0 silenced).
January 18, 2025 - 11:37:14
Django version 5.0.7, using settings 'project.settings'
Starting development server at http://127.0.0.1:8000/
Quit the server with CTRL-BREAK.

Internal Server Error: /
Traceback (most recent call last):
  File "C:\Program Files\Python\Python310\lib\site-packages\django\core\handlers\exception.py", line 55, in inner
    response = get_response(request)
  File "C:\Program Files\Python\Python310\lib\site-packages\django\core\handlers\base.py", line 220, in _get_response
    response = response.render()
  File "C:\Program Files\Python\Python310\lib\site-packages\django\template\response.py", line 114, in render
    self.content = self.rendered_content
  File "C:\Program Files\Python\Python310\lib\site-packages\django\template\response.py", line 90, in rendered_content
    template = self.resolve_template(self.template_name)
  File "C:\Program Files\Python\Python310\lib\site-packages\django\template\response.py", line 72, in resolve_template
    return select_template(template, using=self.using)
  File "C:\Program Files\Python\Python310\lib\site-packages\django\template\loader.py", line 47, in select_template
    raise TemplateDoesNotExist(", ".join(template_name_list), chain=chain)
django.template.exceptions.TemplateDoesNotExist: index.html
[18/Jan/2025 11:37:33] "GET / HTTP/1.1" 500 81391
Not Found: /favicon.ico
[18/Jan/2025 11:37:33] "GET /favicon.ico HTTP/1.1" 404 2441
C:\Users\OK\source\repos\Repository4_python\django_test\login_sys_a\project\settings.py changed, reloading.
Watching for file changes with StatReloader
Performing system checks...

System check identified no issues (0 silenced).
January 18, 2025 - 11:57:26
Django version 5.0.7, using settings 'project.settings'
Starting development server at http://127.0.0.1:8000/
Quit the server with CTRL-BREAK.

Internal Server Error: /
Traceback (most recent call last):
  File "C:\Program Files\Python\Python310\lib\site-packages\django\template\base.py", line 502, in parse
    compile_func = self.tags[command]
KeyError: 'static'

During handling of the above exception, another exception occurred:

Traceback (most recent call last):
  File "C:\Program Files\Python\Python310\lib\site-packages\django\core\handlers\exception.py", line 55, in inner
    response = get_response(request)
  File "C:\Program Files\Python\Python310\lib\site-packages\django\core\handlers\base.py", line 220, in _get_response
    response = response.render()
  File "C:\Program Files\Python\Python310\lib\site-packages\django\template\response.py", line 114, in render
    self.content = self.rendered_content
  File "C:\Program Files\Python\Python310\lib\site-packages\django\template\response.py", line 92, in rendered_content
    return template.render(context, self._request)
  File "C:\Program Files\Python\Python310\lib\site-packages\django\template\backends\django.py", line 61, in render
    return self.template.render(context)
  File "C:\Program Files\Python\Python310\lib\site-packages\django\template\base.py", line 171, in render
    return self._render(context)
  File "C:\Program Files\Python\Python310\lib\site-packages\django\template\base.py", line 163, in _render
    return self.nodelist.render(context)
  File "C:\Program Files\Python\Python310\lib\site-packages\django\template\base.py", line 1000, in render
    return SafeString("".join([node.render_annotated(context) for node in self]))
  File "C:\Program Files\Python\Python310\lib\site-packages\django\template\base.py", line 1000, in <listcomp>
    return SafeString("".join([node.render_annotated(context) for node in self]))
  File "C:\Program Files\Python\Python310\lib\site-packages\django\template\base.py", line 961, in render_annotated
    return self.render(context)
  File "C:\Program Files\Python\Python310\lib\site-packages\django\template\loader_tags.py", line 134, in render
    compiled_parent = self.get_parent(context)
  File "C:\Program Files\Python\Python310\lib\site-packages\django\template\loader_tags.py", line 131, in get_parent
    return self.find_template(parent, context)
  File "C:\Program Files\Python\Python310\lib\site-packages\django\template\loader_tags.py", line 109, in find_template
    template, origin = context.template.engine.find_template(
  File "C:\Program Files\Python\Python310\lib\site-packages\django\template\engine.py", line 159, in find_template
    template = loader.get_template(name, skip=skip)
  File "C:\Program Files\Python\Python310\lib\site-packages\django\template\loaders\cached.py", line 57, in get_template
    template = super().get_template(template_name, skip)
  File "C:\Program Files\Python\Python310\lib\site-packages\django\template\loaders\base.py", line 28, in get_template
    return Template(
  File "C:\Program Files\Python\Python310\lib\site-packages\django\template\base.py", line 154, in __init__
    self.nodelist = self.compile_nodelist()
  File "C:\Program Files\Python\Python310\lib\site-packages\django\template\base.py", line 196, in compile_nodelist
    return parser.parse()
  File "C:\Program Files\Python\Python310\lib\site-packages\django\template\base.py", line 504, in parse
    self.invalid_block_tag(token, command, parse_until)
  File "C:\Program Files\Python\Python310\lib\site-packages\django\template\base.py", line 565, in invalid_block_tag
    raise self.error(
django.template.exceptions.TemplateSyntaxError: Invalid block tag on line 15: 'static'. Did you forget to register or load this tag?
[18/Jan/2025 12:05:54,674] - Broken pipe from ('127.0.0.1', 51190)
Internal Server Error: /
Traceback (most recent call last):
  File "C:\Program Files\Python\Python310\lib\site-packages\django\template\base.py", line 502, in parse
    compile_func = self.tags[command]
KeyError: 'static'

During handling of the above exception, another exception occurred:

Traceback (most recent call last):
  File "C:\Program Files\Python\Python310\lib\site-packages\django\core\handlers\exception.py", line 55, in inner
    response = get_response(request)
  File "C:\Program Files\Python\Python310\lib\site-packages\django\core\handlers\base.py", line 220, in _get_response
    response = response.render()
  File "C:\Program Files\Python\Python310\lib\site-packages\django\template\response.py", line 114, in render
    self.content = self.rendered_content
  File "C:\Program Files\Python\Python310\lib\site-packages\django\template\response.py", line 92, in rendered_content
    return template.render(context, self._request)
  File "C:\Program Files\Python\Python310\lib\site-packages\django\template\backends\django.py", line 61, in render
    return self.template.render(context)
  File "C:\Program Files\Python\Python310\lib\site-packages\django\template\base.py", line 171, in render
    return self._render(context)
  File "C:\Program Files\Python\Python310\lib\site-packages\django\template\base.py", line 163, in _render
    return self.nodelist.render(context)
  File "C:\Program Files\Python\Python310\lib\site-packages\django\template\base.py", line 1000, in render
    return SafeString("".join([node.render_annotated(context) for node in self]))
  File "C:\Program Files\Python\Python310\lib\site-packages\django\template\base.py", line 1000, in <listcomp>
    return SafeString("".join([node.render_annotated(context) for node in self]))
  File "C:\Program Files\Python\Python310\lib\site-packages\django\template\base.py", line 961, in render_annotated
    return self.render(context)
  File "C:\Program Files\Python\Python310\lib\site-packages\django\template\loader_tags.py", line 134, in render
    compiled_parent = self.get_parent(context)
  File "C:\Program Files\Python\Python310\lib\site-packages\django\template\loader_tags.py", line 131, in get_parent
    return self.find_template(parent, context)
  File "C:\Program Files\Python\Python310\lib\site-packages\django\template\loader_tags.py", line 109, in find_template
    template, origin = context.template.engine.find_template(
  File "C:\Program Files\Python\Python310\lib\site-packages\django\template\engine.py", line 159, in find_template
    template = loader.get_template(name, skip=skip)
  File "C:\Program Files\Python\Python310\lib\site-packages\django\template\loaders\cached.py", line 57, in get_template
    template = super().get_template(template_name, skip)
  File "C:\Program Files\Python\Python310\lib\site-packages\django\template\loaders\base.py", line 28, in get_template
    return Template(
  File "C:\Program Files\Python\Python310\lib\site-packages\django\template\base.py", line 154, in __init__
    self.nodelist = self.compile_nodelist()
  File "C:\Program Files\Python\Python310\lib\site-packages\django\template\base.py", line 196, in compile_nodelist
    return parser.parse()
  File "C:\Program Files\Python\Python310\lib\site-packages\django\template\base.py", line 504, in parse
    self.invalid_block_tag(token, command, parse_until)
  File "C:\Program Files\Python\Python310\lib\site-packages\django\template\base.py", line 565, in invalid_block_tag
    raise self.error(
django.template.exceptions.TemplateSyntaxError: Invalid block tag on line 15: 'static'. Did you forget to register or load this tag?
[18/Jan/2025 12:05:54,674] - Broken pipe from ('127.0.0.1', 51191)

C:\Users\OK\source\repos\Repository4_python\django_test\login_sys_a>python manage.py runserver<link rel="icon" type="image/x-icon" href="{% static 'favicon.ico' %}">
コマンドの構文が誤っています。

C:\Users\OK\source\repos\Repository4_python\django_test\login_sys_a>
C:\Users\OK\source\repos\Repository4_python\django_test\login_sys_a>
C:\Users\OK\source\repos\Repository4_python\django_test\login_sys_a>python manage.py runserver
Watching for file changes with StatReloader
Performing system checks...

System check identified no issues (0 silenced).
January 18, 2025 - 12:08:39
Django version 5.0.7, using settings 'project.settings'
Starting development server at http://127.0.0.1:8000/
Quit the server with CTRL-BREAK.

[18/Jan/2025 12:08:47] "GET / HTTP/1.1" 200 936
[18/Jan/2025 12:08:47] "GET /static/favicon.ico HTTP/1.1" 404 1792





*******************

favicon.ico を追加
　root/staticフォルダに　ファイルを追加

base.htmlのheaderに

  {% load static %}
  <link rel="icon" type="image/x-icon" href="{% static 'favicon.ico' %}">
を追加

サーバー再起動、ブラウザでアクセス





