What is doing when exception happens.
Traceback (most recent call last):
  File "C:\Users\OK\source\repos\Repository4_python\logger_test\logger_test_common.py", line 89, in log_test_main
    int("aaa")
ValueError: invalid literal for int() with base 10: 'aaa'
*** logger_class __init__ ***
2021-10-22 01:17:13.205671
message
*** log_test_main ***
Process Start!
info
warning
error
Process End!
What is doing when exception happens.
Traceback (most recent call last):
  File "C:\Users\OK\source\repos\Repository4_python\logger_test\logger_test_common.py", line 89, in log_test_main
    int("aaa")
ValueError: invalid literal for int() with base 10: 'aaa'
*** logger_class __init__ ***
2021-10-22 01:19:25.835908
message
*** log_test_main ***
Process Start!
info
warning
error
Process End!
